Workbook

Sheet Invoices
A1: Date of submission | B1: Dealer Name | C1: Dealer Code | D1: SAP# | E1: Invoice # | F1: Work description | H1: Work Category | I1: Labor | J1: Misc | K1: Parts | L1: Less Insurance | M1: Net for SAP | N1: GST | O1: PST | P1: Total Tax | Q1: tax type | R1: total | S1: Vehicle | T1: 5VIN
A2: 46084 | B2: Westminster Toyota | C2: 1117 | D2: 3600270655 | E2: 10941 | F2: GST portion for repairs | H2: =+VLOOKUP(F2,Categories!A:B,2,) -> Financial / Admin | I2: 1915.95 | J2: 0 | K2: 0 | L2: 0 | M2: =+I2+J2+K2-L2 -> 1915.95 | N2: 0 | O2: 0 | P2: =+N2+O2 -> 0 | Q2: NO TAX | R2: =+ROUND(P2+M2,2) -> 1915.95 | S2: bZ | T2: 27683
A3: 46084 | B3: OpenRoad Toyota Richmond | C3: 1078 | D3: 3600270100 | E3: 361743 | F3: Wheel cover replacement | H3: =+VLOOKUP(F3,Categories!A:B,2,) -> Tires & Wheels | I3: 0 | J3: 0 | K3: 116.62 | L3: 0 | M3: =+I3+J3+K3-L3 -> 116.62 | N3: 5.83 | O3: 8.16 | P3: =+N3+O3 -> 13.99 | Q3: GST + PST | R3: =+ROUND(P3+M3,2) -> 130.61 | S3: bZ | T3: 44818
A4: 46085 | B4: Destination Toyota Burnaby | C4: 1122 | D4: 3600270660 | E4: 694999 | F4: Brakes repair | H4: Repair | I4: 694.95 | J4: 0 | K4: 0 | L4: 0 | M4: =+I4+J4+K4-L4 -> 694.95 | N4: 34.75 | O4: 48.65 | P4: =+N4+O4 -> 83.4 | Q4: GST + PST | R4: =+ROUND(P4+M4,2) -> 778.35 | S4: bZ | T4: 50148
A5: 46085 | B5: Destination Toyota Burnaby | C5: 1122 | D5: 3600270660 | E5: 378998 | F5: Body shop | H5: Repair | I5: 554.65 | J5: =194+112.69 -> 306.69 | K5: 1631.4 | L5: 0 | M5: =+I5+J5+K5-L5 -> 2492.74 | N5: 124.64 | O5: 174.49 | P5: =+N5+O5 -> 299.13 | Q5: No TAX | R5: =+ROUND(P5+M5,2) -> 2791.87 | S5: bZ | T5: 50148
A6: 46091 | B6: OpenRoad Toyota Richmond | C6: 1078 | D6: 3600270750 | E6: 349353 | F6: Rim repair & alignment | H6: =+VLOOKUP(F6,Categories!A:B,2,) -> Tires & Wheels | I6: 189.9 | J6: 350 | K6: 121.1 | L6: 0 | M6: =+I6+J6+K6-L6 -> 661 | N6: 33.06 | O6: 0 | P6: =+N6+O6 -> 33.06 | Q6: =+IF(AND(N6>0,O6=0),"GST ONLY",IF(AND(N6>0,#REF!>=0),"GST + PST","NO TAX")) -> GST ONLY | R6: =+ROUND(P6+M6,2) -> 694.06 | S6: bZ | T6: 49744
A7: 46091 | B7: OpenRoad Toyota Richmond | C7: 1078 | D7: 3600270750 | E7: 335824 | F7: Window Bezel Replacement | H7: Repair | I7: 51.59 | J7: 0 | K7: 155.85 | L7: 0 | M7: =+I7+J7+K7-L7 -> 207.44 | N7: 10.37 | O7: 0 | P7: =+N7+O7 -> 10.37 | Q7: =+IF(AND(N7>0,O7=0),"GST ONLY",IF(AND(N7>0,#REF!>=0),"GST + PST","NO TAX")) -> GST ONLY | R7: =+ROUND(P7+M7,2) -> 217.81 | S7: bZ | T7: 94733
A8: 46091 | B8: OpenRoad Toyota Richmond | C8: 1078 | D8: 3600270750 | E8: 348815 | F8: Hydrogen refuel | H8: =+VLOOKUP(F8,Categories!A:B,2,) -> Fuel & Recharge | I8: 25 | J8: =57.3+2.72 -> 60.02 | K8: 0 | L8: 0 | M8: =+I8+J8+K8-L8 -> 85.02 | N8: 4.26 | O8: 0 | P8: =+N8+O8 -> 4.26 | Q8: =+IF(AND(N8>0,O8=0),"GST ONLY",IF(AND(N8>0,#REF!>=0),"GST + PST","NO TAX")) -> GST ONLY | R8: =+ROUND(P8+M8,2) -> 89.28 | S8: Mirai | T8: 11764
A9: 46091 | B9: Westminster Toyota | C9: 1117 | D9: 3600270769 | E9: 390687 | F9: Windshield replacement | H9: Repair | I9: 0 | J9: 0 | K9: 1496.67 | L9: 0 | M9: =+I9+J9+K9-L9 -> 1496.67 | N9: 74.83 | O9: 104.77 | P9: =+N9+O9 -> 179.6 | Q9: =+IFERROR(+IF(AND(N9>0,O9=0),"GST ONLY",IF(AND(N9>0,O9>=0),"GST + PST","NO TAX")),"") -> GST + PST | R9: =+ROUND(P9+M9,2) -> 1676.27 | S9: bZ | T9: 50229
A10: 46093 | B10: Destination Toyota Burnaby | C10: 1122 | D10: 3600270795 | E10: 378347 | F10: deductible portion plus GST | H10: =+VLOOKUP(F10,Categories!A:B,2,) -> Financial / Admin | I10: 0 | J10: 2500 | K10: 0 | L10: 0 | M10: =+I10+J10+K10-L10 -> 2500 | N10: 326.27 | O10: 0 | P10: =+N10+O10 -> 326.27 | Q10: =+IFERROR(+IF(AND(N10>0,O10=0),"GST ONLY",IF(AND(N10>0,O10>=0),"GST + PST","NO TAX")),"") -> GST ONLY | R10: =+ROUND(P10+M10,2) -> 2826.27 | S10: bZ | T10: 51242
A11: 46093 | B11: Destination Toyota Burnaby | C11: 1122 | D11: 3600270795 | E11: 627377 | F11: Hubcap replacement | H11: =+VLOOKUP(F11,Categories!A:B,2,) -> Tires & Wheels | I11: 0 | J11: 0 | K11: 109.82 | L11: 0 | M11: =+I11+J11+K11-L11 -> 109.82 | N11: 5.49 | O11: 7.69 | P11: =+N11+O11 -> 13.18 | Q11: =+IFERROR(+IF(AND(N11>0,O11=0),"GST ONLY",IF(AND(N11>0,O11>=0),"GST + PST","NO TAX")),"") -> GST + PST | R11: =+ROUND(P11+M11,2) -> 123 | S11: bZ | T11: 51242
A12: 46093 | B12: Destination Toyota Burnaby | C12: 1122 | D12: 3600270795 | E12: 688702 | F12: Bronze cleaning | H12: =+VLOOKUP(F12,Categories!A:B,2,) -> Cleaning | I12: 0 | J12: 130 | K12: 0 | L12: 0 | M12: =+I12+J12+K12-L12 -> 130 | N12: =+M12*0.05 -> 6.5 | O12: =+M12*0.07 -> 9.1 | P12: =+N12+O12 -> 15.6 | Q12: =+IFERROR(+IF(AND(N12>0,O12=0),"GST ONLY",IF(AND(N12>0,O12>=0),"GST + PST","NO TAX")),"") -> GST + PST | R12: =+ROUND(P12+M12,2) -> 145.6 | S12: bZ | T12: 50388
A13: 46093 | B13: Destination Toyota Burnaby | C13: 1122 | D13: 3600270795 | E13: 688702 | F13: Recharge | H13: =+VLOOKUP(F13,Categories!A:B,2,) -> Fuel & Recharge | I13: 0 | J13: 45 | K13: 0 | L13: 0 | M13: =+I13+J13+K13-L13 -> 45 | N13: =+M13*0.05 -> 2.25 | O13: =+M13*0.07 -> 3.15 | P13: =+N13+O13 -> 5.4 | Q13: =+IFERROR(+IF(AND(N13>0,O13=0),"GST ONLY",IF(AND(N13>0,O13>=0),"GST + PST","NO TAX")),"") -> GST + PST | R13: =+ROUND(P13+M13,2) -> 50.4 | S13: bZ | T13: 50388
A14: 46093 | B14: Destination Toyota Burnaby | C14: 1122 | D14: 3600270795 | E14: 690816 | F14: Tire replacement | H14: =+VLOOKUP(F14,Categories!A:B,2,) -> Tires & Wheels | I14: 40 | J14: 6.5 | K14: 408.77 | L14: 0 | M14: =+I14+J14+K14-L14 -> 455.27 | N14: 22.76 | O14: 31.87 | P14: =+N14+O14 -> 54.63 | Q14: =+IFERROR(+IF(AND(N14>0,O14=0),"GST ONLY",IF(AND(N14>0,O14>=0),"GST + PST","NO TAX")),"") -> GST + PST | R14: =+ROUND(P14+M14,2) -> 509.9 | S14: bZ | T14: 50706
A15: 46093 | B15: Destination Toyota Burnaby | C15: 1122 | D15: 3600270795 | E15: 699272 | F15: Cable replacement | H15: Repair | I15: 0 | J15: 75 | K15: 0 | L15: 0 | M15: =+I15+J15+K15-L15 -> 75 | N15: 0 | O15: 0 | P15: =+N15+O15 -> 0 | Q15: =+IFERROR(+IF(AND(N15>0,O15=0),"GST ONLY",IF(AND(N15>0,O15>=0),"GST + PST","NO TAX")),"") -> NO TAX | R15: =+ROUND(P15+M15,2) -> 75 | S15: bZ | T15: 50706
A16: 46093 | B16: Destination Toyota Burnaby | C16: 1122 | D16: 3600270795 | E16: 701767 | F16: Tire replacement | H16: =+VLOOKUP(F16,Categories!A:B,2,) -> Tires & Wheels | I16: 35 | J16: 6.5 | K16: 443.09 | L16: 0 | M16: =+I16+J16+K16-L16 -> 484.59 | N16: 24.23 | O16: 33.92 | P16: =+N16+O16 -> 58.15 | Q16: =+IFERROR(+IF(AND(N16>0,O16=0),"GST ONLY",IF(AND(N16>0,O16>=0),"GST + PST","NO TAX")),"") -> GST + PST | R16: =+ROUND(P16+M16,2) -> 542.74 | S16: bZ | T16: 51361
A17: 46093 | B17: Destination Toyota Burnaby | C17: 1122 | D17: 3600270796 | E17: 694734 | F17: CVI | H17: =+VLOOKUP(F17,Categories!A:B,2,) -> Inspection (CVI) | I17: 209.95 | J17: 0 | K17: 0 | L17: 0 | M17: 209.95 | N17: 10.5 | O17: 14.7 | P17: 25.2 | Q17: GST + PST | R17: 235.15 | S17: bZ | T17: 50104
A18: 46098 | B18: Destination Toyota Burnaby | C18: 1122 | D18: 3600270822 | E18: 704619 | F18: Recharge | H18: =+VLOOKUP(F18,Categories!A:B,2,) -> Fuel & Recharge | I18: 0 | J18: 25 | K18: 0 | L18: 0 | M18: 25 | N18: 0 | O18: 0 | P18: 0 | Q18: NO TAX | R18: 25 | S18: bZ | T18: 51104
A19: 46106 | B19: Jim Pattison Toyota Surrey | C19: 1088 | D19: 3600271656 | E19: 541976 | F19: Wiper replacement | H19: Repair | I19: 17 | J19: 0 | K19: 30 | L19: 0 | M19: 47 | N19: 2.35 | O19: 3.29 | P19: 5.64 | Q19: GST + PST | R19: 52.64 | S19: bZ | T19: 58289
A20: 46106 | B20: Destination Toyota Burnaby | C20: 1122 | D20: 3600271657 | E20: 704724 | F20: CVI | H20: =+VLOOKUP(F20,Categories!A:B,2,) -> Inspection (CVI) | I20: 209.95 | J20: 3.5 | K20: 0 | L20: 0 | M20: =+I20+J20+K20-L20 -> 213.45 | N20: =+M20*0.05 -> 10.6725 | O20: =+M20*0.07 -> 14.9415 | P20: =+N20+O20 -> 25.614 | Q20: =+IFERROR(+IF(AND(N20>0,O20=0),"GST ONLY",IF(AND(N20>0,O20>=0),"GST + PST","NO TAX")),"") -> GST + PST | R20: =+ROUND(P20+M20,2) -> 239.06 | S20: bZ | T20: 94807
A21: 46106 | B21: Destination Toyota Burnaby | C21: 1122 | D21: 3600271657 | E21: 704724 | F21: Rotors service | H21: Repair | I21: =291+388 -> 679 | J21: 0 | K21: 0 | L21: 0 | M21: =+I21+J21+K21-L21 -> 679 | N21: =+M21*0.05 -> 33.95 | O21: =+M21*0.07 -> 47.53 | P21: =+N21+O21 -> 81.48 | Q21: =+IFERROR(+IF(AND(N21>0,O21=0),"GST ONLY",IF(AND(N21>0,O21>=0),"GST + PST","NO TAX")),"") -> GST + PST | R21: =+ROUND(P21+M21,2) -> 760.48 | S21: bZ | T21: 94807
A22: 46106 | B22: Destination Toyota Burnaby | C22: 1122 | D22: 3600271657 | E22: 704725 | F22: CVI | H22: =+VLOOKUP(F22,Categories!A:B,2,) -> Inspection (CVI) | I22: 209.95 | J22: 3.5 | K22: 0 | L22: 0 | M22: =+I22+J22+K22-L22 -> 213.45 | N22: =+M22*0.05 -> 10.6725 | O22: =+M22*0.07 -> 14.9415 | P22: =+N22+O22 -> 25.614 | Q22: =+IFERROR(+IF(AND(N22>0,O22=0),"GST ONLY",IF(AND(N22>0,O22>=0),"GST + PST","NO TAX")),"") -> GST + PST | R22: =+ROUND(P22+M22,2) -> 239.06 | S22: bZ | T22: 94917
A23: 46056 | B23: Destination Toyota Burnaby | C23: 1122 | D23: 3600268565 | E23: 699883 | F23: Recharge | H23: =+VLOOKUP(F23,Categories!A:B,2,) -> Fuel & Recharge | I23: 0 | J23: 25 | K23: 0 | L23: 0 | M23: 25 | N23: 0 | O23: 0 | P23: 0 | Q23: No TAX | R23: 25 | S23: bZ | T23: 94917
A24: 46056 | B24: Westminster Toyota | C24: 1117 | D24: 3600268566 | E24: 267242 | F24: Parts RO | H24: Repair | I24: 0 | J24: 0 | K24: 113.18 | L24: 0 | M24: 113.18 | N24: 5.66 | O24: 7.92 | P24: 13.58 | Q24: GST + PST | R24: 126.76 | S24: bZ | T24: 50463
A25: 46056 | B25: Westminster Toyota | C25: 1117 | D25: 3600268566 | E25: 380217 | F25: Mirai Fuel | H25: =+VLOOKUP(F25,Categories!A:B,2,) -> Fuel & Recharge | I25: 50.73 | J25: 6.09 | K25: 0 | L25: 0 | M25: 56.82 | N25: 2.84 | O25: 3.98 | P25: 6.82 | Q25: GST + PST | R25: 63.64 | S25: Mirai | T25: 08438
A26: 46056 | B26: Westminster Toyota | C26: 1117 | D26: 3600268566 | E26: 385688 | F26: Tire replacement | H26: =+VLOOKUP(F26,Categories!A:B,2,) -> Tires & Wheels | I26: 92.48 | J26: 24.1 | K26: 1097.96 | L26: 0 | M26: 1214.54 | N26: 60.73 | O26: 85.02 | P26: 145.75 | Q26: GST + PST | R26: 1360.29 | S26: bZ | T26: 50565
A27: 46065 | B27: Destination Toyota Burnaby | C27: 1122 | D27: 3600268722 | E27: 700700 | F27: Recharge | H27: =+VLOOKUP(F27,Categories!A:B,2,) -> Fuel & Recharge | I27: 0 | J27: 25 | K27: 0 | L27: 0 | M27: =+I27+J27+K27-L27 -> 25 | N27: 0 | O27: 0 | P27: =+N27+O27 -> 0 | Q27: No TAX | R27: =+ROUND(P27+M27,2) -> 25 | S27: bZ | T27: 51361
A28: 46065 | B28: Destination Toyota Burnaby | C28: 1122 | D28: 3600268722 | E28: 701262 | F28: Recharge | H28: =+VLOOKUP(F28,Categories!A:B,2,) -> Fuel & Recharge | I28: 0 | J28: 25 | K28: 0 | L28: 0 | M28: =+I28+J28+K28-L28 -> 25 | N28: 0 | O28: 0 | P28: =+N28+O28 -> 0 | Q28: No TAX | R28: =+ROUND(P28+M28,2) -> 25 | S28: bZ | T28: 50388
A29: 46072 | B29: Westminster Toyota | C29: 1117 | D29: 3600269377 | E29: 389772 | F29: Windshield Replacement | H29: Repair | I29: 0 | J29: 1496.67 | K29: 0 | L29: 0 | M29: =+I29+J29+K29-L29 -> 1496.67 | N29: 74.83 | O29: 104.77 | P29: =+N29+O29 -> 179.6 | Q29: No TAX | R29: =+ROUND(P29+M29,2) -> 1676.27 | S29: bZ | T29: 50340
A30: 46076 | B30: Destination Toyota Burnaby | C30: 1122 | D30: 3600269601 | E30: 702279 | F30: Recharge | H30: =+VLOOKUP(F30,Categories!A:B,2,) -> Fuel & Recharge | I30: 0 | J30: 25 | K30: 0 | L30: 0 | M30: =+I30+J30+K30-L30 -> 25 | N30: 0 | O30: 0 | P30: =+N30+O30 -> 0 | Q30: No TAX | R30: =+ROUND(P30+M30,2) -> 25 | S30: bZ | T30: 50716
A31: 46077 | B31: Westminster Toyota | C31: 1117 | D31: 10021143 | E31: 10674 | F31: Repair GST payable | H31: =+VLOOKUP(F31,Categories!A:B,2,) -> Financial / Admin | I31: 0 | J31: 0 | K31: 0 | L31: 0 | M31: =+I31+J31+K31-L31 -> 0 | N31: 505.96 | O31: 0 | P31: =+N31+O31 -> 505.96 | Q31: GST only | R31: =+ROUND(P31+M31,2) -> 505.96 | S31: bZ | T31: 27683
A32: 46077 | B32: Westminster Toyota | C32: 1117 | D32: 10021143 | E32: 10675 | F32: Repair GST payable | H32: =+VLOOKUP(F32,Categories!A:B,2,) -> Financial / Admin | I32: 0 | J32: 0 | K32: 0 | L32: 0 | M32: =+I32+J32+K32-L32 -> 0 | N32: 293.44 | O32: 0 | P32: =+N32+O32 -> 293.44 | Q32: GST only | R32: =+ROUND(P32+M32,2) -> 293.44 | S32: bZ | T32: 50006
A33: 46077 | B33: Westminster Toyota | C33: 1117 | D33: 10021143 | E33: 10685 | F33: Repair GST payable | H33: =+VLOOKUP(F33,Categories!A:B,2,) -> Financial / Admin | I33: 0 | J33: 0 | K33: 0 | L33: 0 | M33: =+I33+J33+K33-L33 -> 0 | N33: 124.44 | O33: 0 | P33: =+N33+O33 -> 124.44 | Q33: GST only | R33: =+ROUND(P33+M33,2) -> 124.44 | S33: bZ | T33: 58341
A34: 46035 | B34: OpenRoad Toyota Richmond | C34: 1078 | D34: 3600266854 | E34: 356803 | F34: Tire replacement | H34: =+VLOOKUP(F34,Categories!A:B,2,) -> Tires & Wheels | I34: 120.37 | J34: 6.5 | K34: 413.09 | L34: 0 | M34: =+I34+J34+K34-L34 -> 539.96 | N34: 27 | O34: 0 | P34: =+N34+O34 -> 27 | Q34: GST only | R34: =+ROUND(P34+M34,2) -> 566.96 | S34: bZ | T34: 94817
A35: 46035 | B35: Destination Toyota Burnaby | C35: 1122 | D35: 3600266904 | E35: 696665 | F35: CVI | H35: =+VLOOKUP(F35,Categories!A:B,2,) -> Inspection (CVI) | I35: 669.95 | J35: 0 | K35: 0 | L35: 0 | M35: =+I35+J35+K35-L35 -> 669.95 | N35: 33.5 | O35: 46.9 | P35: =+N35+O35 -> 80.4 | Q35: GST + PST | R35: =+ROUND(P35+M35,2) -> 750.35 | S35: bZ | T35: 51361
A36: 46035 | B36: Destination Toyota Burnaby | C36: 1122 | D36: 3600266904 | E36: 696911 | F36: CVI | H36: =+VLOOKUP(F36,Categories!A:B,2,) -> Inspection (CVI) | I36: 485.95 | J36: 0 | K36: 0 | L36: 0 | M36: =+I36+J36+K36-L36 -> 485.95 | N36: 24.3 | O36: 34.02 | P36: =+N36+O36 -> 58.32 | Q36: GST + PST | R36: =+ROUND(P36+M36,2) -> 544.27 | S36: bZ | T36: 51224
A37: 46035 | B37: Destination Toyota Burnaby | C37: 1122 | D37: 3600266904 | E37: 697579 | F37: CVI | H37: =+VLOOKUP(F37,Categories!A:B,2,) -> Inspection (CVI) | I37: 694.95 | J37: 0 | K37: 0 | L37: 0 | M37: =+I37+J37+K37-L37 -> 694.95 | N37: 34.75 | O37: 48.65 | P37: =+N37+O37 -> 83.4 | Q37: GST + PST | R37: =+ROUND(P37+M37,2) -> 778.35 | S37: bZ | T37: 51104
A38: 46035 | B38: Destination Toyota Burnaby | C38: 1122 | D38: 3600266904 | E38: 697585 | F38: CVI | H38: =+VLOOKUP(F38,Categories!A:B,2,) -> Inspection (CVI) | I38: 209.95 | J38: 0 | K38: 0 | L38: 0 | M38: =+I38+J38+K38-L38 -> 209.95 | N38: 10.5 | O38: 14.7 | P38: =+N38+O38 -> 25.2 | Q38: GST + PST | R38: =+ROUND(P38+M38,2) -> 235.15 | S38: bZ | T38: 50716
A39: 46035 | B39: Destination Toyota Burnaby | C39: 1122 | D39: 3600266904 | E39: 697599 | F39: CVI | H39: =+VLOOKUP(F39,Categories!A:B,2,) -> Inspection (CVI) | I39: 209.95 | J39: 25 | K39: 0 | L39: 0 | M39: =+I39+J39+K39-L39 -> 234.95 | N39: 11.75 | O39: 16.45 | P39: =+N39+O39 -> 28.2 | Q39: GST + PST | R39: =+ROUND(P39+M39,2) -> 263.15 | S39: bZ | T39: 50253
A40: 46043 | B40: OpenRoad Toyota Richmond | C40: 1078 | D40: 3600267134 | E40: 356916 | F40: CVI | H40: =+VLOOKUP(F40,Categories!A:B,2,) -> Inspection (CVI) | I40: 515.85 | J40: 0 | K40: 0 | L40: 0 | M40: =+I40+J40+K40-L40 -> 515.85 | N40: 25.79 | O40: 0 | P40: =+N40+O40 -> 25.79 | Q40: GST only | R40: =+ROUND(P40+M40,2) -> 541.64 | S40: bZ | T40: 49660
...

Sheet Categories
A2: GST portion for repairs | B2: Financial / Admin
A3: Wheel cover replacement | B3: Tires & Wheels
A4: Brakes repair | B4: Maintenance & Repair
A5: Body shop | B5: Maintenance & Repair
A6: Rim repair & alignment | B6: Tires & Wheels
A7: Window Bezel Replacement | B7: Maintenance & Repair
A8: Hydrogen refuel | B8: Fuel & Recharge
A9: Windshield replacement | B9: Maintenance & Repair
A10: deductible portion plus GST | B10: Financial / Admin
A11: Hubcap replacement | B11: Tires & Wheels
A12: Extra cleaning & recharge | B12: Fuel & Recharge
A13: Tire replacement | B13: Tires & Wheels
... A66: bZ repair (front colision) | B66: Maintenance & Repair
